Workbook

Sheet Sales Contract
A1: SALES CONTRACT
A2: No. ERK0508024
A3: Date. 05th AUG, 2024
A5: Shiper/Seller | E5: Consignee/Buyer
A6: GUANGZHOU BIDA TRADING SERVICE CO.,LTD | E6: EUREKA TRADE AND IMPORT EXPORT COMPANY LIMITED
A7: Add: Room 902, Industrial Building 2, Tian 'An Science Park, No. 555 North Panyu Avenue, Panyu District, Guangzhou City, Guangdong Province, China | E7: Add: No. 3, Alley 56, An Son Lane, Dai La Street, Truong Dinh Ward, Hai Ba Trung District, Hanoi City, Vietnam
A8: Tell/Fax: 020-87350250 | E8: Tell/Fax: 089.858.6633
A9: Email: 189619639@QQ.COM | E9: Email: tuvm@erktransport.com
A10: BANK INFORMATION
A11: Bank name: Development Bank of Singapore HONG KONG BRANCH
A12: Bank address: 11th Floor, The Center, 99 Queen's Road Central, Central, Hong Kong
A13: Account name: GUANGZHOU BIDA TRADING SERVICE CO.,LTD
A14: Account number: 79829000348
A15: Swift code: DHBKHKHH (DHBKHKHHXXX，If 11 characters are required)
A16: Benneficiary address: ROOM 902, INDUSTRIAL BUILDING 2, TIAN 'AN SCIENCE PARK, NO. 555 NORTH PANYU AVENUE, PANYU DISTRICT, GUANGZHOU CITY, GUANGDONG PROVINCE, CHINA
A17: Time of shipment | C17: Destination | F17: Payment. | G17: 100% T/T
A18: September, 2024 | C18: From Nansha, China to Hai Phong, Viet Nam | F18: Term. | G18: FOB NANSHA
A20: I) DESCRIPTIONS OF GOODS: | C20: ="Total "&SUM(E23:E25)&" set and pieces of goods" -> Total 57 set and pieces of goods | F20: Orgin. | G20: Made in China
A21: No | B21: Product’s name | C21: Description | D21: Unit | E21: Quantity | F21: Unit price (USD) | G21: Total amount (USD)
A23: 1 | B23: 4-piece set children's outfit | C23: / | D23: SET | E23: 5 | F23: 67100 | G23: 335500
A24: 2 | B24: Zuojueshi men's underwear | C24: AXD100089 | D24: PCE | E24: 29 | F24: 0,5400 | G24: 156600
A25: 3 | B25: Square pocket | C25: 23*23CM | D25: PCE | E25: 23 | F25: 0,4200 | G25: 96600
A26: Total: | F26: USD | G26: =SUM(G23:G25) -> 588700
A27: {="In Words: "&_xll.USD(G26)} -> #NAME?
A28: *Note: This sale contract is made by and between the Seller and the Buyer who are two independent, unrelated businesses without a special relationship with each other. The prices and quantities of goods are agreed upon by the two parties based on the normal negotiation.
A29: II) PAYMENT TERMS
A30: 100% T/T total amount after B/L issueing
A31: III) PACKING
A32: Export standard packing
A33: IV) OTHER
A34: Part shipment | C34: : Allowed
A35: Transhipment | C35: : Allowed
A36: V) FORCE MAJEURE
A37: The Sellers shall not be held responsible for non-delivery or late delivery of the goods due to accidents beyond their control. However, the Sellers shall deliver to the Buyers the documentary evidence(s) of force Majeure cause(s).
A38: VI) ARBITRATION
A39: All disputes in connection with this contract or its execution shall be settled by negotiation. In case no settlement can be reached, the case under dispute shall then be submitted to China International Economic and Trade Arbitration Commission in Beijing for arbitration in accordance with its Arbitration Rules. The decision shall be the final and binding upon both parties. The arbitration fees shall be borne by the losing party.
A40: VII) DOCUMENTS
A41: This contract comes into effect from the signing date. Any changes and/ or amendments to this contract and the annex shall be in writing and subject to agreement by both parties.
A42: This contract shall be in English and the parties shall sign 02 copies. Each party shall have 01 copies. E-signing is acceptable.
A43: This contract can be sent by email.
...

Sheet Comercial Invoice
C1: GUANGZHOU BIDA TRADING SERVICE CO.,LTD
C2: Room 902, industrial building 2, tian 'an science park, no. 555 north panyu avenue, panyu district, guangzhou city, guangdong province, china
A4: COMMERCIAL INVOICE
A5: ='Sales Contract'!A2 -> No. ERK0508024
B7: Consignee/Buyer | G7: Date. | H7: =RIGHT('Sales Contract'!A3,14) -> 05th AUG, 2024
B8: ='Sales Contract'!E6 -> EUREKA TRADE AND IMPORT EXPORT COMPANY LIMITED | G8: Term. | H8: ='Sales Contract'!G18 -> FOB NANSHA
B9: ='Sales Contract'!E7 -> Add: No. 3, Alley 56, An Son Lane, Dai La Street, Truong Dinh Ward, Hai Ba Trung District, Hanoi City, Vietnam
B10: ='Sales Contract'!E8 -> Tell/Fax: 089.858.6633
B12: Payment term | C12: : | D12: ='Sales Contract'!A30 -> 100% T/T total amount after B/L issueing
B13: Part shipment | C13: : | D13: Allowed
B14: Transhipment | C14: : | D14: Allowed
B15: Packing | C15: : | D15: ='Sales Contract'!A32 -> Export standard packing
B16: Origin | C16: : | D16: ='Sales Contract'!G20 -> Made in China
B17: Remarks | C17: :
A19: No | B19: Product’s name | D19: Description | E19: Unit | F19: Quantity | G19: Unit price (USD) | H19: Total amount (USD)
A21: 1 | B21: 4-piece set children's outfit | D21: / | E21: SET | F21: 5 | G21: 67100 | H21: 335500
A22: 2 | B22: Zuojueshi men's underwear | D22: AXD100089 | E22: PCE | F22: 29 | G22: 0,5400 | H22: 156600
A23: 3 | B23: Square pocket | D23: 23*23CM | E23: PCE | F23: 23 | G23: 0,4200 | H23: 96600
A24: Total: | G24: USD | H24: =SUM(H21:H23) -> 588700
A26: {="In Words: "&_xll.USD(H24)} -> #NAME?
A28: BANK INFORMATION:
A29: ='Sales Contract'!A11 -> Bank name: Development Bank of Singapore HONG KONG BRANCH
A30: ='Sales Contract'!A12 -> Bank address: 11th Floor, The Center, 99 Queen's Road Central, Central, Hong Kong
A31: ='Sales Contract'!A13 -> Account name: GUANGZHOU BIDA TRADING SERVICE CO.,LTD
A32: ='Sales Contract'!A14 -> Account number: 79829000348
A33: ='Sales Contract'!A15 -> Swift code: DHBKHKHH (DHBKHKHHXXX，If 11 characters are required)
A34: ='Sales Contract'!A16 -> Benneficiary address: ROOM 902, INDUSTRIAL BUILDING 2, TIAN 'AN SCIENCE PARK, NO. 555 NORTH PANYU AVENUE, PANYU DISTRICT, GUANGZHOU CITY, GUANGDONG PROVINCE, CHINA
F38: GUANGZHOU BIDA TRADING SERVICE CO.,LTD
F47: Director | H47: WANG HAOJUN

Sheet Packing List
C1: GUANGZHOU BIDA TRADING SERVICE CO.,LTD
C2: Room 902, industrial building 2, tian 'an science park, no. 555 north panyu avenue, panyu district, guangzhou city, guangdong province, china
A4: PACKING LIST
A5: ='Sales Contract'!A2 -> No. ERK0508024
B7: Consignee/Buyer | H7: Date. | I7: =RIGHT('Sales Contract'!A3,14) -> 05th AUG, 2024
B8: ='Sales Contract'!E6 -> EUREKA TRADE AND IMPORT EXPORT COMPANY LIMITED | H8: Term. | I8: ='Sales Contract'!G18 -> FOB NANSHA
B9: ='Sales Contract'!E7 -> Add: No. 3, Alley 56, An Son Lane, Dai La Street, Truong Dinh Ward, Hai Ba Trung District, Hanoi City, Vietnam
B10: ='Sales Contract'!E8 -> Tell/Fax: 089.858.6633
B12: Payment term | C12: : | D12: ='Sales Contract'!A30 -> 100% T/T total amount after B/L issueing
B13: Part shipment | C13: : | D13: Allowed
B14: Transhipment | C14: : | D14: Allowed
B15: Packing | C15: : | D15: ='Sales Contract'!A32 -> Export standard packing
B16: Origin | C16: : | D16: ='Sales Contract'!G20 -> Made in China
B17: Remarks | C17: :
A19: No | B19: Product’s name | D19: Description | E19: Unit | F19: Quantity | G19: Packages | H19: G.W (Kgs) | I19: CBM
A21: 1 | B21: 4-piece set children's outfit | D21: / | E21: SET | F21: 5 | G21: 5 | H21: 505.7 | I21: 15.34
A22: 2 | B22: Zuojueshi men's underwear | D22: AXD100089 | E22: PCE | F22: 29 | G22: 15 | H22: 203.11 | I22: 6.23
A23: 3 | B23: Square pocket | D23: 23*23CM | E23: PCE | F23: 23 | G23: 23 | H23: 830.59 | I23: 8.41
A24: Total: | G24: =SUM(G21:G23) -> 43 | H24: =SUM(H21:H23) -> 1539.4 | I24: =SUM(I21:I23) -> 29.98
F29: GUANGZHOU BIDA TRADING SERVICE CO.,LTD
F38: Director | I38: WANG HAOJUN

Sheet Mẫu 1(dự bị)
A1: COMMERCIAL INVOICE
A2: Shiper/Seller | G2: No. | H2: ERK0508024
A3: GUANGZHOU BIDA TRADING SERVICE CO.,LTD | G3: Date. | H3: 05th AUG, 2024
A4: Add: Room 902, Industrial Building 2, Tian 'An Science Park, No. 555 North Panyu Avenue, Panyu District, Guangzhou City, Guangdong Province, China
A5: Tell/Fax: 020-87350250 | G5: No & Date of contract.
A6: Email: 189619639@QQ.COM
A7: Consignee/Buyer | G7: Payment. | H7: 100% T/T
A8: EUREKA TRADE AND IMPORT EXPORT COMPANY LIMITED | G8: Term. | H8: FOB Hai Phong
A9: Add: No. 3, Alley 56, An Son Lane, Dai La Street, Truong Dinh Ward, Hai Ba Trung District, Hanoi City, Vietnam
A10: Tell/Fax: 089.858.6633
A11: Email: doc@erktransport.com
A12: Notify party
A13: SAME AS CONSIGNEE
A14: Port of loading | D14: Final destination
A15: NANSHA, CHINA | D15: HAI PHONG, VIET NAM
A16: Estimate time delivery | D16: Estimate time arrival
A17: 15th Aug, 2024 | D17: 17th Aug, 2024
A18: No | B18: Product’s name | D18: Description | E18: Unit | F18: Quantity | G18: Unit price (USD) | H18: Total amount (USD)
A20: 1 | B20: 4-piece set children's outfit | E20: SET | F20: 5 | G20: 67100 | H20: 335500
A21: 2 | B21: Zuojueshi men's underwear | E21: PCE | F21: 29 | G21: 0,5400 | H21: 156600
A22: 3 | B22: Square pocket | D22: 23*23CM | E22: PCE | F22: 23 | G22: 0,4200 | H22: 96600
A23: Total: | G23: USD | H23: =SUM(H20:H22) -> 588700
A25: {="In Words: "&_xll.USD(H23)} -> In Words: Five hundred and eighty eight thousand seven hundred dollars only.
A27: BANK INFORMATION:
A28: Bank name: Development Bank of Singapore HONG KONG BRANCH
A29: Bank address: 11th Floor, The Center, 99 Queen's Road Central, Central, Hong Kong
A30: Account name: GUANGZHOU BIDA TRADING SERVICE CO.,LTD
A31: Account number: 79829000348
A32: Swift code: DHBKHKHH (DHBKHKHHXXX，If 11 characters are required)
A33: Benneficiary address: Room 902, Industrial Building 2, Tian 'An Science Park, No. 555 North Panyu Avenue, Panyu District, Guangzhou City, Guangdong Province, China
E35: GUANGZHOU BIDA TRADING SERVICE CO.,LTD
E44: Director | H44: WANG HAOJUN

Sheet 申报要素
C1: 产品说明
A3: （1）品名:打气筒（商品编码： 84142000 )
A4: （2）品牌: DECATHLON 中文:迪卡侬; 境外品牌（贴牌生产）
A5: （3）型号：PHP-100
A6: ( 4 ) 是否手动或脚踏：手动
A7: 出口货物在最终目的国（地区）不确定享受优惠关税
D11: 昆山十全塑膠五金產品有限公司
D12: 45820

Sheet 报关单
A1: 中华人民共和国海关出口货物报关单
A2: 境内发货人 | C2: 出境关别 | G2: 出口日期 | K2: 申报日期 | L2: 备案号
A3: 91320583792309777W
A4: 境外收货人 | C4: 运输方式 | G4: 运输工具名称及航次号 | K4: 提运单号
A5: BETO ENGINEERING AND MARKETING CO., LTD. | C5: 江海运输
A6: 生产销售单位 | C6: 监管方式 | G6: 征免性质 | K6: 许可证号
A7: FULL MARK (KUNSHAN)CO.,LTD | C7: 一般贸易 | G7: 一般征税
A8: 合同协议号 | C8: 贸易国（地区） | G8: 运抵国（地区） | K8: 指运港 | L8: 离境口岸
C9: 中国台湾 | G9: 越南 | K9: 越南
A10: 包装种类 | C10: 件数 | D10: 毛重（千克） | G10: 净重(千克) | J10: 成交方式 | K10: 运费 | L10: 保费 | M10: 杂费
A11: 纸箱(22) | C11: 40 | D11: 573.2 | G11: 446 | J11: FOB
A12: 随附单证及编号
A13: 标记唛码及备注
A14: 项号 | B14: 商品编号 | C14: 商品名称及规格型号 | E14: 数量及单位 | G14: 单价 | H14: 总价 | I14: 币别 | J14: 原产国 （地区） | K14: 最终目的国 （地区） | L14: 境内货源地 | M14: 征免
A15: 1 | B15: 8414200000999 | C15: PUMP PHP-100 | E15: 400 | F15: 台 | G15: 8.49 | H15: 3396 | I15: USD | J15: CHINA | K15: 越南 | L15: KUNSHAN
A16: 特殊关系确认：无 价格影响确认：无 支付特许权使用费确认：无 自报自缴：
A17: 报关人员 报关人员证号 电话 兹申明对以上内容承担如实申报、依法纳税之法律责任 | K17: 海关批注及签章
A18: 申报单位: 申报单位（签章）
